<?xml version="1.0" ?>
<!-- =================================================================================== -->
<!-- |    This document was autogenerated by xacro from inobot.urdf.xacro              | -->
<!-- |    EDITING THIS FILE BY HAND IS NOT RECOMMENDED                                 | -->
<!-- =================================================================================== -->
<robot name="inobot">
  <!-- external -->
  <link name="world"/>
  <link name="camera_frame"/>
  <!-- inobot arm -->
  <!-- links -->
  <link name="base_link">
    <inertial>
      <origin rpy="0 0 0" xyz="0.0 0.0 0.0"/>
      <mass value="13.855"/>
      <inertia ixx="0.035465" ixy="0.0" ixz="-0.0" iyy="0.035483" iyz="-6e-06" izz="0.056413"/>
    </inertial>
    <visual>
      <origin rpy="0 0 0" xyz="0 0 0"/>
      <geometry>
        <mesh filename="/home/lukas/inobot/src//inobot_description/meshes/base_link.stl" scale="0.001 0.001 0.001"/>
      </geometry>
      <material name="silver"/>
    </visual>
    <collision>
      <origin rpy="0 0 0" xyz="0 0 0"/>
      <geometry>
        <mesh filename="/home/lukas/inobot/src//inobot_description/meshes/base_link.stl" scale="0.001 0.001 0.001"/>
      </geometry>
    </collision>
  </link>
  <link name="link_1_1">
    <inertial>
      <origin rpy="0 0 0" xyz="0.0 0.0 0.0"/>
      <mass value="12.011"/>
      <inertia ixx="0.06297" ixy="0.0" ixz="-0.0" iyy="0.071" iyz="9.4e-05" izz="0.046659"/>
    </inertial>
    <visual>
      <origin rpy="0 0 0" xyz="0.0 0.0 -0.075"/>
      <geometry>
        <mesh filename="/home/lukas/inobot/src//inobot_description/meshes/link_1_1.stl" scale="0.001 0.001 0.001"/>
      </geometry>
      <material name="silver"/>
    </visual>
    <collision>
      <origin rpy="0 0 0" xyz="0.0 0.0 -0.075"/>
      <geometry>
        <mesh filename="/home/lukas/inobot/src//inobot_description/meshes/link_1_1.stl" scale="0.001 0.001 0.001"/>
      </geometry>
    </collision>
  </link>
  <link name="link_2_1">
    <inertial>
      <origin rpy="0 0 0" xyz="0.0 0.0 0.075"/>
      <mass value="15.936"/>
      <inertia ixx="0.134333" ixy="-2.7e-05" ixz="-0.000521" iyy="0.140602" iyz="7.6e-05" izz="0.030731"/>
    </inertial>
    <visual>
      <origin rpy="0 0 0" xyz="0.0 0.0 -0.238"/>
      <geometry>
        <mesh filename="/home/lukas/inobot/src//inobot_description/meshes/link_2_1.stl" scale="0.001 0.001 0.001"/>
      </geometry>
      <material name="silver"/>
    </visual>
    <collision>
      <origin rpy="0 0 0" xyz="0.0 0.0 -0.238"/>
      <geometry>
        <mesh filename="/home/lukas/inobot/src//inobot_description/meshes/link_2_1.stl" scale="0.001 0.001 0.001"/>
      </geometry>
    </collision>
  </link>
  <link name="link_3_1">
    <inertial>
      <origin rpy="0 0 0" xyz="0.0 0.0 0.0155"/>
      <mass value="5.041004757219209"/>
      <inertia ixx="0.009332" ixy="-2e-06" ixz="-4.5e-05" iyy="0.009148" iyz="6.6e-05" izz="0.005579"/>
    </inertial>
    <visual>
      <origin rpy="0 0 0" xyz="0.0 0.0 -0.459"/>
      <geometry>
        <mesh filename="/home/lukas/inobot/src//inobot_description/meshes/link_3_1.stl" scale="0.001 0.001 0.001"/>
      </geometry>
      <material name="silver"/>
    </visual>
    <collision>
      <origin rpy="0 0 0" xyz="0.0 0.0 -0.459"/>
      <geometry>
        <mesh filename="/home/lukas/inobot/src//inobot_description/meshes/link_3_1.stl" scale="0.001 0.001 0.001"/>
      </geometry>
    </collision>
  </link>
  <link name="link_4_1">
    <inertial>
      <origin rpy="0 0 0" xyz="0.0 0.0 0.0"/>
      <mass value="3.5598085247676114"/>
      <inertia ixx="0.008642" ixy="1e-06" ixz="-7.4e-05" iyy="0.009421" iyz="-1.6e-05" izz="0.003882"/>
    </inertial>
    <visual>
      <origin rpy="0 0 0" xyz="0.0 0.0 -0.56"/>
      <geometry>
        <mesh filename="/home/lukas/inobot/src//inobot_description/meshes/link_4_1.stl" scale="0.001 0.001 0.001"/>
      </geometry>
      <material name="silver"/>
    </visual>
    <collision>
      <origin rpy="0 0 0" xyz="0.0 0.0 -0.56"/>
      <geometry>
        <mesh filename="/home/lukas/inobot/src//inobot_description/meshes/link_4_1.stl" scale="0.001 0.001 0.001"/>
      </geometry>
    </collision>
  </link>
  <link name="link_5_1">
    <inertial>
      <origin rpy="0 0 0" xyz="0.0 0.0 0.004"/>
      <mass value="1.3072389659535424"/>
      <inertia ixx="0.000919" ixy="0.0" ixz="3e-06" iyy="0.000767" iyz="-1.6e-05" izz="0.000684"/>
    </inertial>
    <visual>
      <origin rpy="0 0 0" xyz="0.0 0.0 -0.683"/>
      <geometry>
        <mesh filename="/home/lukas/inobot/src//inobot_description/meshes/link_5_1.stl" scale="0.001 0.001 0.001"/>
      </geometry>
      <material name="silver"/>
    </visual>
    <collision>
      <origin rpy="0 0 0" xyz="0.0 0.0 -0.683"/>
      <geometry>
        <mesh filename="/home/lukas/inobot/src//inobot_description/meshes/link_5_1.stl" scale="0.001 0.001 0.001"/>
      </geometry>
    </collision>
  </link>
  <link name="link_6_1">
    <inertial>
      <origin rpy="0 0 0" xyz="0.0 0.0 0.040"/>
      <mass value="0.16956132368991875"/>
      <inertia ixx="2.5e-05" ixy="-0.0" ixz="0.0" iyy="2.5e-05" iyz="-0.0" izz="4.1e-05"/>
    </inertial>
    <visual>
      <origin rpy="0 0 0" xyz="0.0 0.0 -0.734"/>
      <geometry>
        <mesh filename="/home/lukas/inobot/src//inobot_description/meshes/link_6_1.stl" scale="0.001 0.001 0.001"/>
      </geometry>
      <material name="silver"/>
    </visual>
    <collision>
      <origin rpy="0 0 0" xyz="0.0 0.0 -0.734"/>
      <geometry>
        <mesh filename="/home/lukas/inobot/src//inobot_description/meshes/link_6_1.stl" scale="0.001 0.001 0.001"/>
      </geometry>
    </collision>
  </link>
  <link name="tcp">
      
    </link>
  <!-- joints -->
  <joint name="fixed" type="fixed">
    <parent link="world"/>
    <child link="base_link"/>
  </joint>
  <joint name="link_1_joint" type="revolute">
    <origin rpy="0 0 -1.57" xyz="0.0 0.0 0.075"/>
    <parent link="base_link"/>
    <child link="link_1_1"/>
    <axis xyz="0.0 0.0 -1.0"/>
    <limit effort="150" lower="-2.1" upper="2.1" velocity="1.0"/>
  </joint>
  <joint name="link_2_joint" type="revolute">
    <origin rpy="0 0 0" xyz="0.0 0.0 0.163"/>
    <parent link="link_1_1"/>
    <child link="link_2_1"/>
    <axis xyz="-1.0 0.0 0.0"/>
    <limit effort="150" lower="-1.5" upper="1.5" velocity="1.0"/>
  </joint>
  <joint name="link_3_joint" type="revolute">
    <origin rpy="0 0 0" xyz="0.0 0.0 0.221"/>
    <parent link="link_2_1"/>
    <child link="link_3_1"/>
    <axis xyz="-1.0 0.0 0.0"/>
    <limit effort="150" lower="-1.5" upper="1.5" velocity="1.0"/>
  </joint>
  <joint name="link_4_joint" type="revolute">
    <origin rpy="0 0 0" xyz="0.0 0.0 0.10"/>
    <parent link="link_3_1"/>
    <child link="link_4_1"/>
    <axis xyz="0.0 0.0 -1.0"/>
    <limit effort="150" lower="-1.5" upper="1.5" velocity="1.0"/>
  </joint>
  <joint name="link_5_joint" type="revolute">
    <origin rpy="0 0 0" xyz="0.0 0.0 0.123"/>
    <parent link="link_4_1"/>
    <child link="link_5_1"/>
    <axis xyz="-1.0 0.0 0.0"/>
    <limit effort="150" lower="-1.5" upper="1.5" velocity="1.0"/>
  </joint>
  <joint name="link_6_joint" type="revolute">
    <origin rpy="0 0 0" xyz="0.0 0.0 0.05"/>
    <parent link="link_5_1"/>
    <child link="link_6_1"/>
    <axis xyz="0.0 0.0 -1.0"/>
    <limit effort="150" lower="-3.14" upper="3.14" velocity="1.0"/>
  </joint>
  <joint name="tcp_joint" type="fixed">
    <origin rpy="0 0 0" xyz="0.0 0.0 0.13"/>
    <parent link="link_6_1"/>
    <child link="tcp"/>
    <axis xyz="0.0 0.0 -1.0"/>
    <limit effort="150" lower="-3.14" upper="3.14" velocity="1.0"/>
  </joint>
  <joint name="world_to_camera" type="fixed">
    <parent link="world"/>
    <child link="camera_frame"/>
    <origin rpy="0 0 0" xyz="0.0 -0.5 1.25"/>
  </joint>
  <ros2_control name="InobotHardwareInterface" type="system">
    <hardware>
      <plugin>fake_components/GenericSystem</plugin>
      <param name="fake_sensor_commands">False</param>
      <param name="state_following_offset">0.0</param>
    </hardware>
    <joint name="link_1_joint">
      <command_interface name="position">
        <param name="min"> -100 </param>
        <param name="max"> 100 </param>
      </command_interface>
      <command_interface name="velocity">
        <param name="min">-1</param>
        <param name="max">1</param>
      </command_interface>
      <command_interface name="acceleration">
        <param name="min">-1</param>
        <param name="max">1</param>
      </command_interface>
      <state_interface name="position"/>
      <state_interface name="velocity"/>
      <state_interface name="acceleration"/>
    </joint>
    <joint name="link_2_joint">
      <command_interface name="position">
        <param name="min"> -100 </param>
        <param name="max"> 100 </param>
      </command_interface>
      <command_interface name="velocity">
        <param name="min">-1</param>
        <param name="max">1</param>
      </command_interface>
      <command_interface name="acceleration">
        <param name="min">-1</param>
        <param name="max">1</param>
      </command_interface>
      <state_interface name="position"/>
      <state_interface name="velocity"/>
      <state_interface name="acceleration"/>
    </joint>
    <joint name="link_3_joint">
      <command_interface name="position">
        <param name="min"> -100 </param>
        <param name="max"> 100 </param>
      </command_interface>
      <command_interface name="velocity">
        <param name="min">-1</param>
        <param name="max">1</param>
      </command_interface>
      <command_interface name="acceleration">
        <param name="min">-1</param>
        <param name="max">1</param>
      </command_interface>
      <state_interface name="position"/>
      <state_interface name="velocity"/>
      <state_interface name="acceleration"/>
    </joint>
    <joint name="link_4_joint">
      <command_interface name="position">
        <param name="min"> -100 </param>
        <param name="max"> 100 </param>
      </command_interface>
      <command_interface name="velocity">
        <param name="min">-1</param>
        <param name="max">1</param>
      </command_interface>
      <command_interface name="acceleration">
        <param name="min">-1</param>
        <param name="max">1</param>
      </command_interface>
      <state_interface name="position"/>
      <state_interface name="velocity"/>
      <state_interface name="acceleration"/>
    </joint>
    <joint name="link_5_joint">
      <command_interface name="position">
        <param name="min"> -100 </param>
        <param name="max"> 100 </param>
      </command_interface>
      <command_interface name="velocity">
        <param name="min">-1</param>
        <param name="max">1</param>
      </command_interface>
      <command_interface name="acceleration">
        <param name="min">-1</param>
        <param name="max">1</param>
      </command_interface>
      <state_interface name="position"/>
      <state_interface name="velocity"/>
      <state_interface name="acceleration"/>
    </joint>
    <joint name="link_6_joint">
      <command_interface name="position">
        <param name="min"> -100 </param>
        <param name="max"> 100 </param>
      </command_interface>
      <command_interface name="velocity">
        <param name="min">-1</param>
        <param name="max">1</param>
      </command_interface>
      <command_interface name="acceleration">
        <param name="min">-1</param>
        <param name="max">1</param>
      </command_interface>
      <state_interface name="position"/>
      <state_interface name="velocity"/>
      <state_interface name="acceleration"/>
    </joint>
  </ros2_control>


<!-- <gazebo>
  <plugin filename="libgazebo_ros2_control.so" name="control"/>
</gazebo> -->
<gazebo reference="base_link">
  <material> <ambient>0 0 0.8 1</ambient>
        <diffuse>0 0 0.8 1</diffuse>
        <specular>0 0 0.8 1</specular></material>
  <mu1>0.2</mu1>
  <mu2>0.2</mu2>
  <selfCollide>true</selfCollide>
  <gravity>true</gravity>
</gazebo>

<gazebo reference="link_1_1">
  <material> <ambient>0 0 0.8 1</ambient>
        <diffuse>0 0 0.8 1</diffuse>
        <specular>0 0 0.8 1</specular></material>
  <mu1>0.2</mu1>
  <mu2>0.2</mu2>
  <selfCollide>true</selfCollide>
  <gravity>true</gravity>
</gazebo>

<gazebo reference="link_2_1">
  <material> <ambient>0 0 0.8 1</ambient>
        <diffuse>0 0 0.8 1</diffuse>
        <specular>0 0 0.8 1</specular></material>
  <mu1>0.2</mu1>
  <mu2>0.2</mu2>
  <selfCollide>true</selfCollide>
  <gravity>true</gravity>
</gazebo>

<gazebo reference="link_3_1">
  <material> <ambient>0 0 0.8 1</ambient>
        <diffuse>0 0 0.8 1</diffuse>
        <specular>0 0 0.8 1</specular></material>
  <mu1>0.2</mu1>
  <mu2>0.2</mu2>
  <selfCollide>true</selfCollide>
  <gravity>true</gravity>
</gazebo>

<gazebo reference="link_4_1">
  <material> <ambient>0 0 0.8 1</ambient>
        <diffuse>0 0 0.8 1</diffuse>
        <specular>0 0 0.8 1</specular></material>
  <mu1>0.2</mu1>
  <mu2>0.2</mu2>
  <selfCollide>true</selfCollide>
  <gravity>true</gravity>
</gazebo>

<gazebo reference="link_5_1">
  <material> <ambient>0 0 0.8 1</ambient>
        <diffuse>0 0 0.8 1</diffuse>
        <specular>0 0 0.8 1</specular></material>
  <mu1>0.2</mu1>
  <mu2>0.2</mu2>
  <selfCollide>true</selfCollide>
  <gravity>true</gravity>
</gazebo>

<gazebo reference="link_6_1">
  <material> <ambient>0 0 0.8 1</ambient>
        <diffuse>0 0 0.8 1</diffuse>
        <specular>0 0 0.8 1</specular></material>
  <mu1>0.2</mu1>
  <mu2>0.2</mu2>
  <selfCollide>true</selfCollide>
  <gravity>true</gravity>
</gazebo>

<gazebo reference="">
  <material> <ambient>0 0 0.8 1</ambient>
        <diffuse>0 0 0.8 1</diffuse>
        <specular>0 0 0.8 1</specular></material>
  <mu1>0.2</mu1>
  <mu2>0.2</mu2>
  <selfCollide>true</selfCollide>
  <gravity>true</gravity>
</gazebo>

  <ros2_control name="IgnitionSystem" type="system">
    <hardware>
      <plugin>ign_ros2_control/IgnitionSystem</plugin>
    </hardware>
    <joint name="link_1_joint">
      <command_interface name="position">
        <param name="min">-15</param>
        <param name="max">15</param>
      </command_interface>
      <state_interface name="position"/>
      <state_interface name="velocity"/>
      <state_interface name="effort"/>
    </joint>
  </ros2_control>

   <gazebo>
    <!-- Joint state publisher -->
    <plugin filename="libign_ros2_control-system.so" name="ign_ros2_control">
      <robot_param>robot_description</robot_param>
      <robot_param_node>robot_state_publisher</robot_param_node>
      <parameters>$(find inobot_moveit_config)/config/ros_controllers.yaml</parameters>
    </plugin>
  </gazebo>

</robot>
